<?xml version="1.0"?>

<robot name="pan_tilt" xmlns:xacro="http://www.ros.org/wiki/xacro">
    <link name="base_link">
        <visual>
            <origin xyz="0.00 0.00 0.00" rpy="0.00 0.00 0.00"/>
            <geometry>
                <mesh filename="package://pan_tilt_description/meshes/Base-Link.STL" />
            </geometry>
        </visual>
        <collision>
            <origin xyz="0.00 0.00 0.00" rpy="0.00 0.00 0.00"/>
            <geometry>
                <mesh filename="package://pan_tilt_description/meshes/Base-Link-col.STL" />
            </geometry>
        </collision>
        <inertial>
            <mass value="0.022"/>
            <origin xyz="0.000 0.000 0.007" rpy="0.0 0.0 0.0"/>
            <inertia ixx="0.000009" ixy="0.000000" ixz="0.000000"
                     iyy="0.000003" iyz="0.000000"
                     izz="0.000009" />
        </inertial>
    </link>

    <joint name="tilt_joint" type="revolute">
        <parent link="base_link"/>
        <child link="tilt_link"/>
        <origin xyz="0.00 -0.025 0.022" rpy="0.00 0.00 0.00"/>
        <axis xyz="0 1 0"/>
        <limit velocity="3.14" effort="10" lower="-3.14" upper="3.14"/>
    </joint>

    <link name="tilt_link">
        <visual>
            <origin xyz="0.00 0.00 0.00" rpy="0.00 0.00 0.00"/>
            <geometry>
                <mesh filename="package://pan_tilt_description/meshes/Tilt-Link.STL" />
            </geometry>
        </visual>
        <collision>
            <origin xyz="0.00 0.00 0.00" rpy="0.00 0.00 0.00"/>
            <geometry>
                <mesh filename="package://pan_tilt_description/meshes/Tilt-Link-col.STL" />
            </geometry>
        </collision>
        <inertial>
            <mass value="0.070"/>
            <origin xyz="-0.005 0.025 0.010" rpy="0.0 0.0 0.0"/>
            <inertia ixx="0.000016" ixy="0.000000" ixz="0.000000"
                     iyy="0.000016" iyz="0.000000"
                     izz="0.000011" />
        </inertial>
    </link>

    <joint name="pan_joint" type="revolute">
        <parent link="tilt_link"/>
        <child link="pan_link"/>
        <origin xyz="0.00 0.025 0.042" rpy="0.00 0.00 0.00"/>
        <axis xyz="0 0 1"/>
        <limit velocity="3.14" effort="10" lower="-3.14" upper="3.14"/>
    </joint>

    <link name="pan_link">
        <visual>
            <origin xyz="0.00 0.00 0.00" rpy="0.00 0.00 0.00"/>
            <geometry>
                <mesh filename="package://pan_tilt_description/meshes/Pan-Link.STL" />
            </geometry>
        </visual>
        <collision>
            <origin xyz="0.00 0.00 0.00" rpy="0.00 0.00 0.00"/>
            <geometry>
                <mesh filename="package://pan_tilt_description/meshes/Pan-Link-col.STL" />
            </geometry>
        </collision>
        <inertial>
            <mass value="0.011"/>
            <origin xyz="0.004 0.000 0.014" rpy="0.0 0.0 0.0"/>
            <inertia ixx="0.000001" ixy="0.000000" ixz="0.000000"
                     iyy="0.000001" iyz="0.000000"
                     izz="0.000001" />
        </inertial>
    </link>

    <joint name="end_effector_fixed_joint" type="fixed">
        <parent link="pan_link"/>
        <child link="end_effector_link"/>
        <origin xyz="0.023 0.00 0.015" rpy="0.00 0.00 0.00"/>
    </joint>

    <link name="end_effector_link">
    </link>

</robot>